<mujoco model="humanoid_arms">
  <option iterations="50" timestep="0.001" solver="PGS" gravity="0 0 -9.81" />

  <compiler angle="radian" meshdir="../meshes" eulerseq="zyx" autolimits="true" />

  <default>
    <joint limited="true" damping="0.01" armature="0.01" frictionloss="0.01" />
    <geom condim="4" contype="1" conaffinity="15" friction="0.9 0.2 0.2" solref="0.001 2" />
    <motor ctrllimited="true" />
    <equality solref="0.001 2" />
    <default class="visualgeom">
      <geom material="visualgeom" condim="1" contype="0" conaffinity="0" />
    </default>
  </default>

  <asset>
    <mesh name="pelvis" content_type="model/stl" file="pelvis.stl" />
    <mesh name="waist_yaw_link" content_type="model/stl" file="waist_yaw_link.stl" />
    <mesh name="shoulder_pitch_l_link" content_type="model/stl" file="shoulder_pitch_l_link.stl" />
    <mesh name="shoulder_roll_l_link" content_type="model/stl" file="shoulder_roll_l_link.stl" />
    <mesh name="shoulder_yaw_l_link" content_type="model/stl" file="shoulder_yaw_l_link.stl" />
    <mesh name="elbow_pitch_l_link" content_type="model/stl" file="elbow_pitch_l_link.stl" />
    <mesh name="elbow_yaw_l_link" content_type="model/stl" file="elbow_yaw_l_link.stl" />
    <mesh name="wrist_pitch_l_link" content_type="model/stl" file="wrist_pitch_l_link.stl" />
    <mesh name="wrist_roll_l_link" content_type="model/stl" file="wrist_roll_l_link.stl" />
    <mesh name="shoulder_pitch_r_link" content_type="model/stl" file="shoulder_pitch_r_link.stl" />
    <mesh name="shoulder_roll_r_link" content_type="model/stl" file="shoulder_roll_r_link.stl" />
    <mesh name="shoulder_yaw_r_link" content_type="model/stl" file="shoulder_yaw_r_link.stl" />
    <mesh name="elbow_pitch_r_link" content_type="model/stl" file="elbow_pitch_r_link.stl" />
    <mesh name="elbow_yaw_r_link" content_type="model/stl" file="elbow_yaw_r_link.stl" />
    <mesh name="wrist_pitch_r_link" content_type="model/stl" file="wrist_pitch_r_link.stl" />
    <mesh name="wrist_roll_r_link" content_type="model/stl" file="wrist_roll_r_link.stl" />
    <texture name="texplane" type="2d" builtin="checker" rgb1=".0 .0 .0" rgb2=".8 .8 .8" width="100" height="100" />
    <material name="matplane" reflectance="0." texture="texplane" texrepeat="1 1" texuniform="true" />
    <material name="visualgeom" rgba="0.5 0.9 0.2 1" />
  </asset>

  <worldbody>
    <light directional="true" diffuse="0.4 0.4 0.4" specular="0.1 0.1 0.1" pos="0 0 5.0" dir="0 0 -1" castshadow="false" />
    <light directional="true" diffuse="0.6 0.6 0.6" specular="0.2 0.2 0.2" pos="0 0 4" dir="0 0 -1" />
    <geom name="ground" type="plane" pos="0 0 0" size="100 100 0.001" quat="1 0 0 0" material="matplane" condim="3" conaffinity="15" />
    <camera name="fixed" pos="0 -3.0 0.7263660907303516" xyaxes="1 0 0 0 0 1" />
    <camera name="track" mode="trackcom" pos="0 -3.0 0.7263660907303516" xyaxes="1 0 0 0 0 1" />
    <body name="root" pos="0 0 0.22636609073035163" quat="1 0 0 0">
      <!-- <freejoint name="root" /> -->
      <site name="imu" size="0.01" pos="0 0 0" />
      <geom type="mesh" rgba="0.752941 0.752941 0.752941 1" mesh="pelvis" contype="1" conaffinity="0" density="0" group="1" class="visualgeom" />
      <geom type="mesh" rgba="0.752941 0.752941 0.752941 1" mesh="pelvis" />
      <body name="waist_yaw_link">
        <inertial pos="-0.000568 0.00056 0.231488" quat="0.999972 -0.000556372 -0.00687121 -0.00296446" mass="22.4452" diaginertia="0.429083 0.379054 0.177094" />
        <joint name="waist_yaw_joint" pos="0 0 0" axis="0 0 1" range="-2.96 3.14" actuatorfrcrange="-120 120" />
        <geom type="mesh" rgba="0.752941 0.752941 0.752941 1" mesh="waist_yaw_link" contype="1" conaffinity="0" density="0" group="1" class="visualgeom" />
        <geom type="mesh" rgba="0.752941 0.752941 0.752941 1" mesh="waist_yaw_link" />
        <body name="shoulder_pitch_l_link" pos="0 0.14539 0.37721" quat="0.999048 0.0436192 0 0">
          <inertial pos="0.00754 0.064361 -3.7e-05" quat="0.401219 0.582335 -0.401019 0.582317" mass="1.03063" diaginertia="0.000636 0.000545537 0.000470463" />
          <joint name="shoulder_pitch_l_joint" pos="0 0 0" axis="0 1 0" range="-2.96 2.96" actuatorfrcrange="-91 91" />
          <geom type="mesh" rgba="0.752941 0.752941 0.752941 1" mesh="shoulder_pitch_l_link" contype="1" conaffinity="0" density="0" group="1" class="visualgeom" />
          <geom type="mesh" rgba="0.752941 0.752941 0.752941 1" mesh="shoulder_pitch_l_link" />
          <body name="shoulder_roll_l_link" pos="0 0.068 0">
            <inertial pos="0.00106653 0.00220629 -0.0441161" quat="0.7082 -0.00329147 -0.0128765 0.705886" mass="0.412601" diaginertia="0.00126407 0.000939019 0.000895909" />
            <joint name="shoulder_roll_l_joint" pos="0 0 0" axis="1 0 0" range="-0.2618 3.4" actuatorfrcrange="-60 60" />
            <geom type="mesh" rgba="0.752941 0.752941 0.752941 1" mesh="shoulder_roll_l_link" contype="1" conaffinity="0" density="0" group="1" class="visualgeom" />
            <geom type="mesh" rgba="0.752941 0.752941 0.752941 1" mesh="shoulder_roll_l_link" />
            <body name="shoulder_yaw_l_link" pos="0 0 -0.1025">
              <inertial pos="0.008387 0.00373 -0.11229" quat="0.95062 -0.00536915 0.0606486 0.304326" mass="1.3076" diaginertia="0.00944038 0.00923249 0.000707129" />
              <joint name="shoulder_yaw_l_joint" pos="0 0 0" axis="0 0 1" range="-2.96 2.96" actuatorfrcrange="-30 30" />
              <geom type="mesh" rgba="0.752941 0.752941 0.752941 1" mesh="shoulder_yaw_l_link" contype="1" conaffinity="0" density="0" group="1" class="visualgeom" />
              <geom type="mesh" rgba="0.752941 0.752941 0.752941 1" mesh="shoulder_yaw_l_link" />
              <body name="elbow_pitch_l_link" pos="0.02 0 -0.1975">
                <inertial pos="-0.014369 -9e-05 -0.024267" quat="0.501992 0.622759 -0.464622 0.379872" mass="0.222661" diaginertia="0.000398305 0.000361097 0.000199597" />
                <joint name="elbow_pitch_l_joint" pos="0 0 0" axis="0 1 0" range="-2.61 0.261" actuatorfrcrange="-30 30" />
                <geom type="mesh" rgba="0.752941 0.752941 0.752941 1" mesh="elbow_pitch_l_link" contype="1" conaffinity="0" density="0" group="1" class="visualgeom" />
                <geom type="mesh" rgba="0.752941 0.752941 0.752941 1" mesh="elbow_pitch_l_link" />
                <body name="elbow_yaw_l_link" pos="-0.02 0 -0.0543">
                  <inertial pos="8e-05 0.00115 -0.069083" quat="0.999899 -0.012607 0.000668448 0.00659261" mass="0.990079" diaginertia="0.00296102 0.00287955 0.000420432" />
                  <joint name="elbow_yaw_l_joint" pos="0 0 0" axis="0 0 1" range="-2.9671 2.9671" actuatorfrcrange="-15 15" />
                  <geom type="mesh" rgba="0.752941 0.752941 0.752941 1" mesh="elbow_yaw_l_link" contype="1" conaffinity="0" density="0" group="1" class="visualgeom" />
                  <geom type="mesh" rgba="0.752941 0.752941 0.752941 1" mesh="elbow_yaw_l_link" />
                  <body name="wrist_pitch_l_link" pos="0 0.002 -0.1887">
                    <inertial pos="0.005341 0.000652 -0.018511" quat="0.314863 0.66524 0.28303 0.614988" mass="0.266415" diaginertia="0.000116841 0.000110463 7.36959e-05" />
                    <joint name="wrist_pitch_l_joint" pos="0 0 0" axis="0 1 0" range="-1.3 1.65" actuatorfrcrange="-9 9" />
                    <geom type="mesh" rgba="0.752941 0.752941 0.752941 1" mesh="wrist_pitch_l_link" contype="1" conaffinity="0" density="0" group="1" class="visualgeom" />
                    <geom type="mesh" rgba="0.752941 0.752941 0.752941 1" mesh="wrist_pitch_l_link" />
                    <body name="wrist_roll_l_link" pos="5.0485e-05 0 -0.02">
                      <inertial pos="0.001596 0.000155 -0.018822" quat="0.497592 0.500808 0.515059 0.486114" mass="0.065684" diaginertia="7.30062e-05 6.40263e-05 3.29676e-05" />
                      <joint name="wrist_roll_l_joint" pos="0 0 0" axis="1 0 0" range="-1.04 0.785" actuatorfrcrange="-9 9" />
                      <geom type="mesh" rgba="0.752941 0.752941 0.752941 1" mesh="wrist_roll_l_link" contype="1" conaffinity="0" density="0" group="1" class="visualgeom" />
                      <geom type="mesh" rgba="0.752941 0.752941 0.752941 1" mesh="wrist_roll_l_link" />
                    </body>
                  </body>
                </body>
              </body>
            </body>
          </body>
        </body>
        <body name="shoulder_pitch_r_link" pos="0 -0.14539 0.37721" quat="0.999048 -0.0436192 0 0">
          <inertial pos="0.00754 -0.064361 -3.7e-05" quat="0.582335 0.401219 -0.582317 0.401019" mass="1.03063" diaginertia="0.000636 0.000545537 0.000470463" />
          <joint name="shoulder_pitch_r_joint" pos="0 0 0" axis="0 1 0" range="-2.96 2.96" actuatorfrcrange="-91 91" />
          <geom type="mesh" rgba="0.752941 0.752941 0.752941 1" mesh="shoulder_pitch_r_link" contype="1" conaffinity="0" density="0" group="1" class="visualgeom" />
          <geom type="mesh" rgba="0.752941 0.752941 0.752941 1" mesh="shoulder_pitch_r_link" />
          <body name="shoulder_roll_r_link" pos="0 -0.068 0">
            <inertial pos="0.00106653 -0.00220629 -0.0441161" quat="0.705886 -0.0128765 -0.00329147 0.7082" mass="0.412601" diaginertia="0.00126407 0.000939019 0.000895909" />
            <joint name="shoulder_roll_r_joint" pos="0 0 0" axis="1 0 0" range="-3.4 0.2618" actuatorfrcrange="-60 60" />
            <geom type="mesh" rgba="0.752941 0.752941 0.752941 1" mesh="shoulder_roll_r_link" contype="1" conaffinity="0" density="0" group="1" class="visualgeom" />
            <geom type="mesh" rgba="0.752941 0.752941 0.752941 1" mesh="shoulder_roll_r_link" />
            <body name="shoulder_yaw_r_link" pos="0 0 -0.1025">
              <inertial pos="0.008387 -0.00373 -0.11229" quat="0.95062 0.00536915 0.0606486 -0.304326" mass="1.3076" diaginertia="0.00944038 0.00923249 0.000707129" />
              <joint name="shoulder_yaw_r_joint" pos="0 0 0" axis="0 0 1" range="-2.96 2.96" actuatorfrcrange="-30 30" />
              <geom type="mesh" rgba="0.752941 0.752941 0.752941 1" mesh="shoulder_yaw_r_link" contype="1" conaffinity="0" density="0" group="1" class="visualgeom" />
              <geom type="mesh" rgba="0.752941 0.752941 0.752941 1" mesh="shoulder_yaw_r_link" />
              <body name="elbow_pitch_r_link" pos="0.02 0 -0.1975">
                <inertial pos="-0.014369 9e-05 -0.024267" quat="0.622759 0.501992 -0.379872 0.464622" mass="0.222661" diaginertia="0.000398305 0.000361097 0.000199597" />
                <joint name="elbow_pitch_r_joint" pos="0 0 0" axis="0 1 0" range="-2.61 0.261" actuatorfrcrange="-30 30" />
                <geom type="mesh" rgba="0.752941 0.752941 0.752941 1" mesh="elbow_pitch_r_link" contype="1" conaffinity="0" density="0" group="1" class="visualgeom" />
                <geom type="mesh" rgba="0.752941 0.752941 0.752941 1" mesh="elbow_pitch_r_link" />
                <body name="elbow_yaw_r_link" pos="-0.02 0 -0.0543">
                  <inertial pos="8e-05 0.00115 -0.069083" quat="0.999899 -0.012607 0.000668448 0.00659261" mass="0.990079" diaginertia="0.00296102 0.00287955 0.000420432" />
                  <joint name="elbow_yaw_r_joint" pos="0 0 0" axis="0 0 1" range="-2.9671 2.9671" actuatorfrcrange="-15 15" />
                  <geom type="mesh" rgba="0.752941 0.752941 0.752941 1" mesh="elbow_yaw_r_link" contype="1" conaffinity="0" density="0" group="1" class="visualgeom" />
                  <geom type="mesh" rgba="0.752941 0.752941 0.752941 1" mesh="elbow_yaw_r_link" />
                  <body name="wrist_pitch_r_link" pos="0 -0.002 -0.1887">
                    <inertial pos="0.005341 -0.000652 -0.018511" quat="0.614988 0.28303 0.66524 0.314863" mass="0.266415" diaginertia="0.000116841 0.000110463 7.36959e-05" />
                    <joint name="wrist_pitch_r_joint" pos="0 0 0" axis="0 1 0" range="-1.3 1.65" actuatorfrcrange="-9 9" />
                    <geom type="mesh" rgba="0.752941 0.752941 0.752941 1" mesh="wrist_pitch_r_link" contype="1" conaffinity="0" density="0" group="1" class="visualgeom" />
                    <geom type="mesh" rgba="0.752941 0.752941 0.752941 1" mesh="wrist_pitch_r_link" />
                    <body name="wrist_roll_r_link" pos="5.0485e-05 0 -0.02">
                      <inertial pos="0.001596 -0.000155 -0.018822" quat="0.486114 0.515059 0.500808 0.497592" mass="0.065684" diaginertia="7.30062e-05 6.40263e-05 3.29676e-05" />
                      <joint name="wrist_roll_r_joint" pos="0 0 0" axis="1 0 0" range="-1.04 0.785" actuatorfrcrange="-9 9" />
                      <geom type="mesh" rgba="0.752941 0.752941 0.752941 1" mesh="wrist_roll_r_link" contype="1" conaffinity="0" density="0" group="1" class="visualgeom" />
                      <geom type="mesh" rgba="0.752941 0.752941 0.752941 1" mesh="wrist_roll_r_link" />
                    </body>
                  </body>
                </body>
              </body>
            </body>
          </body>
        </body>
      </body>
    </body>
  </worldbody>

  <actuator>
    <motor name="waist_yaw_joint" joint="waist_yaw_joint" ctrllimited="true" ctrlrange="-120 120" gear="1" />
    <motor name="shoulder_pitch_l_joint" joint="shoulder_pitch_l_joint" ctrllimited="true" ctrlrange="-91 91" gear="1" />
    <motor name="shoulder_roll_l_joint" joint="shoulder_roll_l_joint" ctrllimited="true" ctrlrange="-60 60" gear="1" />
    <motor name="shoulder_yaw_l_joint" joint="shoulder_yaw_l_joint" ctrllimited="true" ctrlrange="-30 30" gear="1" />
    <motor name="elbow_pitch_l_joint" joint="elbow_pitch_l_joint" ctrllimited="true" ctrlrange="-30 30" gear="1" />
    <motor name="elbow_yaw_l_joint" joint="elbow_yaw_l_joint" ctrllimited="true" ctrlrange="-15 15" gear="1" />
    <motor name="wrist_pitch_l_joint" joint="wrist_pitch_l_joint" ctrllimited="true" ctrlrange="-9 9" gear="1" />
    <motor name="wrist_roll_l_joint" joint="wrist_roll_l_joint" ctrllimited="true" ctrlrange="-9 9" gear="1" />
    <motor name="shoulder_pitch_r_joint" joint="shoulder_pitch_r_joint" ctrllimited="true" ctrlrange="-91 91" gear="1" />
    <motor name="shoulder_roll_r_joint" joint="shoulder_roll_r_joint" ctrllimited="true" ctrlrange="-60 60" gear="1" />
    <motor name="shoulder_yaw_r_joint" joint="shoulder_yaw_r_joint" ctrllimited="true" ctrlrange="-30 30" gear="1" />
    <motor name="elbow_pitch_r_joint" joint="elbow_pitch_r_joint" ctrllimited="true" ctrlrange="-30 30" gear="1" />
    <motor name="elbow_yaw_r_joint" joint="elbow_yaw_r_joint" ctrllimited="true" ctrlrange="-15 15" gear="1" />
    <motor name="wrist_pitch_r_joint" joint="wrist_pitch_r_joint" ctrllimited="true" ctrlrange="-9 9" gear="1" />
    <motor name="wrist_roll_r_joint" joint="wrist_roll_r_joint" ctrllimited="true" ctrlrange="-9 9" gear="1" />
  </actuator>

  <sensor>
    <actuatorpos name="waist_yaw_joint_p" actuator="waist_yaw_joint" />
    <actuatorvel name="waist_yaw_joint_v" actuator="waist_yaw_joint" />
    <actuatorfrc name="waist_yaw_joint_f" actuator="waist_yaw_joint" noise="0.001" />
    <actuatorpos name="shoulder_pitch_l_joint_p" actuator="shoulder_pitch_l_joint" />
    <actuatorvel name="shoulder_pitch_l_joint_v" actuator="shoulder_pitch_l_joint" />
    <actuatorfrc name="shoulder_pitch_l_joint_f" actuator="shoulder_pitch_l_joint" noise="0.001" />
    <actuatorpos name="shoulder_roll_l_joint_p" actuator="shoulder_roll_l_joint" />
    <actuatorvel name="shoulder_roll_l_joint_v" actuator="shoulder_roll_l_joint" />
    <actuatorfrc name="shoulder_roll_l_joint_f" actuator="shoulder_roll_l_joint" noise="0.001" />
    <actuatorpos name="shoulder_yaw_l_joint_p" actuator="shoulder_yaw_l_joint" />
    <actuatorvel name="shoulder_yaw_l_joint_v" actuator="shoulder_yaw_l_joint" />
    <actuatorfrc name="shoulder_yaw_l_joint_f" actuator="shoulder_yaw_l_joint" noise="0.001" />
    <actuatorpos name="elbow_pitch_l_joint_p" actuator="elbow_pitch_l_joint" />
    <actuatorvel name="elbow_pitch_l_joint_v" actuator="elbow_pitch_l_joint" />
    <actuatorfrc name="elbow_pitch_l_joint_f" actuator="elbow_pitch_l_joint" noise="0.001" />
    <actuatorpos name="elbow_yaw_l_joint_p" actuator="elbow_yaw_l_joint" />
    <actuatorvel name="elbow_yaw_l_joint_v" actuator="elbow_yaw_l_joint" />
    <actuatorfrc name="elbow_yaw_l_joint_f" actuator="elbow_yaw_l_joint" noise="0.001" />
    <actuatorpos name="wrist_pitch_l_joint_p" actuator="wrist_pitch_l_joint" />
    <actuatorvel name="wrist_pitch_l_joint_v" actuator="wrist_pitch_l_joint" />
    <actuatorfrc name="wrist_pitch_l_joint_f" actuator="wrist_pitch_l_joint" noise="0.001" />
    <actuatorpos name="wrist_roll_l_joint_p" actuator="wrist_roll_l_joint" />
    <actuatorvel name="wrist_roll_l_joint_v" actuator="wrist_roll_l_joint" />
    <actuatorfrc name="wrist_roll_l_joint_f" actuator="wrist_roll_l_joint" noise="0.001" />
    <actuatorpos name="shoulder_pitch_r_joint_p" actuator="shoulder_pitch_r_joint" />
    <actuatorvel name="shoulder_pitch_r_joint_v" actuator="shoulder_pitch_r_joint" />
    <actuatorfrc name="shoulder_pitch_r_joint_f" actuator="shoulder_pitch_r_joint" noise="0.001" />
    <actuatorpos name="shoulder_roll_r_joint_p" actuator="shoulder_roll_r_joint" />
    <actuatorvel name="shoulder_roll_r_joint_v" actuator="shoulder_roll_r_joint" />
    <actuatorfrc name="shoulder_roll_r_joint_f" actuator="shoulder_roll_r_joint" noise="0.001" />
    <actuatorpos name="shoulder_yaw_r_joint_p" actuator="shoulder_yaw_r_joint" />
    <actuatorvel name="shoulder_yaw_r_joint_v" actuator="shoulder_yaw_r_joint" />
    <actuatorfrc name="shoulder_yaw_r_joint_f" actuator="shoulder_yaw_r_joint" noise="0.001" />
    <actuatorpos name="elbow_pitch_r_joint_p" actuator="elbow_pitch_r_joint" />
    <actuatorvel name="elbow_pitch_r_joint_v" actuator="elbow_pitch_r_joint" />
    <actuatorfrc name="elbow_pitch_r_joint_f" actuator="elbow_pitch_r_joint" noise="0.001" />
    <actuatorpos name="elbow_yaw_r_joint_p" actuator="elbow_yaw_r_joint" />
    <actuatorvel name="elbow_yaw_r_joint_v" actuator="elbow_yaw_r_joint" />
    <actuatorfrc name="elbow_yaw_r_joint_f" actuator="elbow_yaw_r_joint" noise="0.001" />
    <actuatorpos name="wrist_pitch_r_joint_p" actuator="wrist_pitch_r_joint" />
    <actuatorvel name="wrist_pitch_r_joint_v" actuator="wrist_pitch_r_joint" />
    <actuatorfrc name="wrist_pitch_r_joint_f" actuator="wrist_pitch_r_joint" noise="0.001" />
    <actuatorpos name="wrist_roll_r_joint_p" actuator="wrist_roll_r_joint" />
    <actuatorvel name="wrist_roll_r_joint_v" actuator="wrist_roll_r_joint" />
    <actuatorfrc name="wrist_roll_r_joint_f" actuator="wrist_roll_r_joint" noise="0.001" />
    <framequat name="orientation" objtype="site" noise="0.001" objname="imu" />
    <gyro name="angular-velocity" site="imu" noise="0.005" cutoff="34.9" />
  </sensor>
</mujoco>