<?xml version="1.0" encoding="utf-8"?>
<robot name="humanoid_arms">

  <!-- Base link: pelvis -->
  <link name="pelvis">
    <inertial>
      <origin xyz="-0.000641 0.000723 -0.074769" rpy="0 0 0"/>
      <mass value="6.094610"/>
      <inertia ixx="0.020607" ixy="0.004335" ixz="0.000046" iyy="0.027481" iyz="-0.000037" izz="0.028105"/>
    </inertial>
    <visual>
      <geometry>
        <mesh filename="package://tiangong_description/meshes/pelvis.stl"/>
      </geometry>
      <material name="">
        <color rgba="0.752941176470588 0.752941176470588 0.752941176470588 1"/>
      </material>
    </visual>
    <collision>
      <geometry>
        <mesh filename="package://tiangong_description/meshes/pelvis.stl"/>
      </geometry>
    </collision>
  </link>

  <!-- Waist yaw joint and link -->
  <link name="waist_yaw_link">
    <inertial>
      <origin xyz="-0.000568 0.000560 0.231488" rpy="0 0 0"/>
      <mass value="22.445155"/>
      <inertia ixx="0.429034" ixy="-0.000293" ixz="0.003462" iyy="0.379055" iyz="-0.000237" izz="0.177142"/>
    </inertial>
    <visual>
      <geometry>
        <mesh filename="package://tiangong_description/meshes/waist_yaw_link.stl"/>
      </geometry>
      <material name="">
        <color rgba="0.752941176470588 0.752941176470588 0.752941176470588 1"/>
      </material>
    </visual>
    <collision>
      <geometry>
        <mesh filename="package://tiangong_description/meshes/waist_yaw_link.stl"/>
      </geometry>
    </collision>
  </link>

  <joint name="waist_yaw_joint" type="revolute">
    <origin xyz="0 0 0" rpy="0 0 0"/>
    <parent link="pelvis"/>
    <child link="waist_yaw_link"/>
    <axis xyz="0 0 1"/>
    <limit effort="120" lower="-2.96" upper="3.14" velocity="7.0"/>
  </joint>

  <!-- Right Arm Components -->
  <link name="shoulder_pitch_r_link">
    <inertial>
      <origin xyz="0.007540 -0.064361 -0.000037" rpy="0 0 0"/>
      <mass value="1.030628"/>
      <inertia ixx="0.000536" ixy="-0.000025" ixz="1.26194941072712E-08" iyy="0.000480" iyz="-2.95758293199811E-08" izz="0.000636"/>
    </inertial>
    <visual>
      <geometry>
        <mesh filename="package://tiangong_description/meshes/shoulder_pitch_r_link.stl"/>
      </geometry>
      <material name="">
        <color rgba="0.752941176470588 0.752941176470588 0.752941176470588 1"/>
      </material>
    </visual>
    <collision>
      <geometry>
        <mesh filename="package://tiangong_description/meshes/shoulder_pitch_r_link.stl"/>
      </geometry>
    </collision>
  </link>

  <joint name="shoulder_pitch_r_joint" type="revolute">
    <origin xyz="0 -0.14539 0.37721" rpy="-0.087266 0 0"/>
    <parent link="waist_yaw_link"/>
    <child link="shoulder_pitch_r_link"/>
    <axis xyz="0 1 0"/>
    <limit effort="91" lower="-2.96" upper="2.96" velocity="8.8"/>
  </joint>

  <link name="shoulder_roll_r_link">
    <inertial>
      <origin xyz="0.00106653447924365 -0.00220628914286614 -0.0441160803631309" rpy="0 0 0"/>
      <mass value="0.412600522097283"/>
      <inertia ixx="0.000939" ixy="-0.000001" ixz="0.000001" iyy="0.001264" iyz="-0.000005" izz="0.000896"/>
    </inertial>
    <visual>
      <geometry>
        <mesh filename="package://tiangong_description/meshes/shoulder_roll_r_link.stl"/>
      </geometry>
      <material name="">
        <color rgba="0.752941176470588 0.752941176470588 0.752941176470588 1"/>
      </material>
    </visual>
    <collision>
      <geometry>
        <mesh filename="package://tiangong_description/meshes/shoulder_roll_r_link.stl"/>
      </geometry>
    </collision>
  </link>

  <joint name="shoulder_roll_r_joint" type="revolute">
    <origin xyz="0 -0.068 0" rpy="0 0 0"/>
    <parent link="shoulder_pitch_r_link"/>
    <child link="shoulder_roll_r_link"/>
    <axis xyz="1 0 0"/>
    <limit effort="60" lower="-3.4" upper="0.2618" velocity="12"/>
  </joint>

  <link name="shoulder_yaw_r_link">
    <inertial>
      <origin xyz="0.008387 -0.003730 -0.112290" rpy="0 0 0"/>
      <mass value="1.307604"/>
      <inertia ixx="0.009261" ixy="-0.000052" ixz="-0.000968" iyy="0.009283" iyz="0.000413" izz="0.000836"/>
    </inertial>
    <visual>
      <geometry>
        <mesh filename="package://tiangong_description/meshes/shoulder_yaw_r_link.stl"/>
      </geometry>
      <material name="">
        <color rgba="0.752941176470588 0.752941176470588 0.752941176470588 1"/>
      </material>
    </visual>
    <collision>
      <geometry>
        <mesh filename="package://tiangong_description/meshes/shoulder_yaw_r_link.stl"/>
      </geometry>
    </collision>
  </link>

  <joint name="shoulder_yaw_r_joint" type="revolute">
    <origin xyz="0 0 -0.1025" rpy="0 0 0"/>
    <parent link="shoulder_roll_r_link"/>
    <child link="shoulder_yaw_r_link"/>
    <axis xyz="0 0 1"/>
    <limit effort="30" lower="-2.96" upper="2.96" velocity="7.3"/>
  </joint>

  <link name="elbow_pitch_r_link">
    <inertial>
      <origin xyz="-0.014369 0.000090 -0.024267" rpy="0 0 0"/>
      <mass value="0.222661"/>
      <inertia ixx="0.000364" ixy="0.000001" ixz="0.000010" iyy="0.000208" iyz="3.96645947452354E-05" izz="0.000387"/>
    </inertial>
    <visual>
      <geometry>
        <mesh filename="package://tiangong_description/meshes/elbow_pitch_r_link.stl"/>
      </geometry>
      <material name="">
        <color rgba="0.752941176470588 0.752941176470588 0.752941176470588 1"/>
      </material>
    </visual>
    <collision>
      <geometry>
        <mesh filename="package://tiangong_description/meshes/elbow_pitch_r_link.stl"/>
      </geometry>
    </collision>
  </link>

  <joint name="elbow_pitch_r_joint" type="revolute">
    <origin xyz="0.02 0 -0.1975" rpy="0 0 0"/>
    <parent link="shoulder_yaw_r_link"/>
    <child link="elbow_pitch_r_link"/>
    <axis xyz="0 1 0"/>
    <limit effort="30" lower="-2.61" upper="0.261" velocity="7.3"/>
  </joint>

  <link name="elbow_yaw_r_link">
    <inertial>
      <origin xyz="0.000080 0.001150 -0.069083" rpy="0 0 0"/>
      <mass value="0.990079"/>
      <inertia ixx="0.002961" ixy="0.000001" ixz="-0.000003" iyy="0.002878" iyz="-0.000062" izz="0.000422"/>
    </inertial>
    <visual>
      <geometry>
        <mesh filename="package://tiangong_description/meshes/elbow_yaw_r_link.stl"/>
      </geometry>
      <material name="">
        <color rgba="0.752941176470588 0.752941176470588 0.752941176470588 1"/>
      </material>
    </visual>
    <collision>
      <geometry>
        <mesh filename="package://tiangong_description/meshes/elbow_yaw_r_link.stl"/>
      </geometry>
    </collision>
  </link>

  <joint name="elbow_yaw_r_joint" type="revolute">
    <origin xyz="-0.02 0 -0.0543" rpy="0 0 0"/>
    <parent link="elbow_pitch_r_link"/>
    <child link="elbow_yaw_r_link"/>
    <axis xyz="0 0 1"/>
    <limit effort="15" lower="-2.9671" upper="2.9671" velocity="14.6"/>
  </joint>

  <link name="wrist_pitch_r_link">
    <inertial>
      <origin xyz="0.005341 -0.000652 -0.018511" rpy="0 0 0"/>
      <mass value="0.266415"/>
      <inertia ixx="0.000074" ixy="-0.000003" ixz="0.000002" iyy="0.000114" iyz="-0.000003" izz="0.000113"/>
    </inertial>
    <visual>
      <geometry>
        <mesh filename="package://tiangong_description/meshes/wrist_pitch_r_link.stl"/>
      </geometry>
      <material name="">
        <color rgba="0.752941176470588 0.752941176470588 0.752941176470588 1"/>
      </material>
    </visual>
    <collision>
      <geometry>
        <mesh filename="package://tiangong_description/meshes/wrist_pitch_r_link.stl"/>
      </geometry>
    </collision>
  </link>

  <joint name="wrist_pitch_r_joint" type="revolute">
    <origin xyz="0 -0.002 -0.1887" rpy="0 0 0"/>
    <parent link="elbow_yaw_r_link"/>
    <child link="wrist_pitch_r_link"/>
    <axis xyz="0 1 0"/>
    <limit effort="9" lower="-1.3" upper="1.65" velocity="7.2"/>
  </joint>

  <link name="wrist_roll_r_link">
    <inertial>
      <origin xyz="0.001596 -0.000155 -0.018822" rpy="0 0 0"/>
      <mass value="0.065684"/>
      <inertia ixx="0.000033" ixy="1.01838157154324E-07" ixz="0.000001" iyy="0.000073" iyz="2.28155013652257E-07" izz="0.000064"/>
    </inertial>
    <visual>
      <geometry>
        <mesh filename="package://tiangong_description/meshes/wrist_roll_r_link.stl"/>
      </geometry>
      <material name="">
        <color rgba="0.752941176470588 0.752941176470588 0.752941176470588 1"/>
      </material>
    </visual>
    <collision>
      <geometry>
        <mesh filename="package://tiangong_description/meshes/wrist_roll_r_link.stl"/>
      </geometry>
    </collision>
  </link>

  <joint name="wrist_roll_r_joint" type="revolute">
    <origin xyz="5.0485E-05 0 -0.02" rpy="0 0 0"/>
    <parent link="wrist_pitch_r_link"/>
    <child link="wrist_roll_r_link"/>
    <axis xyz="1 0 0"/>
    <limit effort="9" lower="-1.04" upper="0.785" velocity="7.2"/>
  </joint>

</robot>