<mujoco model="zhiyuan scene">
  <compiler angle='radian' eulerseq="XYZ" meshdir="../meshes"  autolimits="true" />

  <option timestep="0.001" />

  <visual>
    <global azimuth="150" elevation="-20" />
    <headlight ambient="0.3 0.3 0.3" diffuse="0.6 0.6 0.6" specular="0 0 0" />
    <scale forcewidth="0.03" contactwidth="0.01" contactheight="0.02" com="1" framelength="0.6"
      framewidth="0.05" />
    <rgba haze="0.15 0.25 0.35 1" com="0.502 1 0 0.5" contactpoint="1 1 0.6 0.4"
      contactforce="0.98 0.4 0.4 1" />
  </visual>
  <!-- <statistic extent="1.1" center="0 0 0.55" /> -->
  <default>
      <geom contype = "0" conaffinity = "0" solref = "0.005 1" condim = "3" friction = "1 1" />
      <equality solref = "0.005 1" />
      <default class = "zhiyuan">
      </default>
      <default class = "collision">
          <geom contype = "1" group = "3" type = "capsule" />
          <default class = "collision-left">
              <geom contype = "2" conaffinity = "4" />
          </default>
          <default class = "collision-right">
              <geom contype = "4" conaffinity = "2" />
          </default>
      </default>
    </default>
  <asset>
    <mesh name="base_link_simple" file="base_link_simple.STL"/>
    <mesh name="body_yaw" file="lumber_yaw.STL" />
    <mesh name="body_roll" file="lumber_roll.STL" />
    <mesh name="body_pitch" file="lumber_pitch.STL" />
    <mesh name="left_shoulder_pitch" file="left_shoulder_pitch.STL"/>
    <mesh name="left_shoulder_roll" file="left_shoulder_roll.STL"/>
    <mesh name="left_shoulder_yaw" file="left_shoulder_yaw.STL"/>
    <mesh name="left_elbow_pitch" file="left_elbow_pitch.STL"/>
    <mesh name="left_elbow_yaw" file="left_elbow_yaw.STL"/>
    <mesh name="left_wrist_pitch" file="left_wrist_pitch.STL"/>
    <mesh name="right_shoulder_pitch" file="right_shoulder_pitch.STL"/>
    <mesh name="right_shoulder_roll" file="right_shoulder_roll.STL"/>
    <mesh name="right_shoulder_yaw" file="right_shoulder_yaw.STL"/>
    <mesh name="right_elbow_pitch" file="right_elbow_pitch.STL"/>
    <mesh name="right_elbow_yaw" file="right_elbow_yaw.STL"/>
    <mesh name="right_wrist_pitch" file="right_wrist_pitch.STL"/>
    <mesh name="waist_motor_a_link" file="waist_motor_a_link.STL"/>
    <mesh name="waist_motor_a_ball" file="waist_motor_a_ball.STL"/>
    <mesh name="waist_motor_a_loop" file="waist_motor_a_loop.STL"/>
    <mesh name="waist_motor_b_link" file="waist_motor_b_link.STL"/>
    <mesh name="waist_motor_b_ball" file="waist_motor_b_ball.STL"/>
    <mesh name="waist_motor_b_loop" file="waist_motor_b_loop.STL"/>
    <mesh name="left_hip_pitch" file="left_hip_pitch.STL"/>
    <mesh name="left_hip_roll" file="left_hip_roll.STL"/>
    <mesh name="left_hip_yaw" file="left_hip_yaw.STL"/>
    <mesh name="left_knee_pitch" file="left_knee_pitch.STL"/>
    <mesh name="left_ankle_pitch" file="left_ankle_pitch.STL"/>
    <mesh name="left_ankle_roll" file="left_ankle_roll.STL"/>
    <mesh name="leg_l_toe_a_link" file="leg_l_toe_a_link.STL"/>
    <mesh name="leg_l_toe_a_ball" file="leg_l_toe_a_ball.STL"/>
    <mesh name="leg_l_toe_a_loop" file="leg_l_toe_a_loop.STL"/>
    <mesh name="leg_l_toe_b_link" file="leg_l_toe_b_link.STL"/>
    <mesh name="leg_l_toe_b_ball" file="leg_l_toe_b_ball.STL"/>
    <mesh name="leg_l_toe_b_loop" file="leg_l_toe_b_loop.STL"/>
    <mesh name="right_hip_pitch" file="right_hip_pitch.STL"/>
    <mesh name="right_hip_roll" file="right_hip_roll.STL"/>
    <mesh name="right_hip_yaw" file="right_hip_yaw.STL"/>
    <mesh name="right_knee_pitch" file="right_knee_pitch.STL"/>
    <mesh name="right_ankle_pitch" file="right_ankle_pitch.STL"/>
    <mesh name="right_ankle_roll" file="right_ankle_roll.STL"/>
    <mesh name="leg_r_toe_a_link" file="leg_r_toe_a_link.STL"/>
    <mesh name="leg_r_toe_a_ball" file="leg_r_toe_a_ball.STL"/>
    <mesh name="leg_r_toe_a_loop" file="leg_r_toe_a_loop.STL"/>
    <mesh name="leg_r_toe_b_link" file="leg_r_toe_b_link.STL"/>
    <mesh name="leg_r_toe_b_ball" file="leg_r_toe_b_ball.STL"/>
    <mesh name="leg_r_toe_b_loop" file="leg_r_toe_b_loop.STL"/>
    <mesh name="arm_r_wrist_a_ball" file="arm_r_wrist_a_ball.STL"/>
    <mesh name="arm_r_wrist_motor_a_link" file="arm_r_wrist_motor_a_link.STL"/>
    <mesh name="arm_r_wrist_a_loop" file="arm_r_wrist_a_loop.STL"/>
    <mesh name="arm_r_wrist_b_ball" file="arm_r_wrist_b_ball.STL"/>
    <mesh name="arm_r_wrist_motor_b_link" file="arm_r_wrist_motor_b_link.STL"/>
    <mesh name="arm_r_wrist_b_loop" file="arm_r_wrist_b_loop.STL"/>
  </asset>

  <worldbody>
    <body name="A1-body" pos="0 0 0.8">
      <inertial pos="0.00252285 -0.00063439 0.0302341" quat="0.703473 0.710702 -0.00394586 0.00368824" mass="4.30416" diaginertia="0.0268062 0.0218101 0.0108301"/>
      <freejoint name="floating_base"/>
      <geom pos="-0.05 -0.1 -0.073" type="mesh" contype="0" conaffinity="0" group="1" density="0" rgba="0.8 0.4 0 1" mesh="base_link_simple"/>
      <geom pos="-0.05 -0.1 -0.073" type="mesh" rgba="0.8 0.4 0 1" mesh="base_link_simple"/>
      <camera name="track" pos="0 -3 1" quat="0.850651 0.525731 0 0" mode="track" />
      <site name = "imu" size = "0.01" pos = "0 0 0" />
      
      <body name="body_yaw" pos="0.00245 0 0.115534" quat="1 0 0 -2.27456e-05">
        <inertial pos="-0.0180007 1.4e-06 0.0243298" quat="-7.72625e-06 0.78309 -2.54549e-05 0.621909" mass="0.362519" diaginertia="0.000655093 0.00045823 0.000342457"/>
        <geom type="mesh" contype="0" conaffinity="0" group="1" density="0" rgba="1 0.4 0.4 1" mesh="body_yaw"/>
        <body name="body_roll" pos="0 0 0.0405" quat="0.5 0.5 -0.5 -0.5">
          <inertial pos="-0.00029919 0.0003642 -0.00019197" quat="0.773215 -0.138631 -0.0225684 0.618394" mass="0.0341207" diaginertia="5.46439e-06 4.90308e-06 4.81253e-06"/>
          <geom type="mesh" contype="0" conaffinity="0" group="1" density="0" rgba="1 0.4 0.4 1" mesh="body_roll"/>
          <body name="body_pitch" quat="0.707107 0 0.707107 0">
            <inertial pos="0.00070244 0.210726 -0.00117164" quat="0.701682 0.712112 -0.0198998 -0.0119722" mass="8.85711" diaginertia="0.147956 0.111655 0.0606701"/>
            <geom type="mesh" contype="0" conaffinity="0" group="1" density="0" rgba="0.4 1 0.4 1" mesh="body_pitch"/>
            <body name="left_shoulder_pitch" pos="0 0.256 -0.1458" quat="0 0 0 -1">
              <inertial pos="-0.00251212 -0.00149141 -0.0567447" quat="0.995975 -0.00474479 -0.0345991 0.0825443" mass="1.00679" diaginertia="0.00108562 0.000958162 0.000853398"/>
              <geom type="mesh" contype="0" conaffinity="0" group="1" density="0" rgba="1 0.4 0.4 1" mesh="left_shoulder_pitch"/>
              <body name="left_shoulder_roll" pos="-0.0313 0 -0.0592" quat="0.707105 0 -0.707108 0">
                <inertial pos="0.000154 0.0778464 -0.0271134" quat="0.765297 0.643563 -0.00747942 0.00959688" mass="0.691695" diaginertia="0.00133677 0.00119611 0.000636982"/>
                <geom type="mesh" contype="0" conaffinity="0" group="1" density="0" rgba="1 1 0.4 1" mesh="left_shoulder_roll"/>
                <body name="left_shoulder_yaw" pos="0 0.1252 -0.0313" quat="0.5 0.5 0.5 -0.5">
                  <inertial pos="-2.68e-06 0.00182113 -0.00392718" quat="0.695603 -0.0321904 0.0318975 0.716996" mass="0.725594" diaginertia="0.00118335 0.00116041 0.000481204"/>
                  <geom type="mesh" contype="0" conaffinity="0" group="1" density="0" rgba="0.4 1 0.4 1" mesh="left_shoulder_yaw"/>
                  <body name="left_elbow_pitch" pos="0 -0.031 -0.0365" quat="0.707107 -0.707107 0 0">
                    <inertial pos="2.604e-05 0.0752824 0.0268658" quat="0.597053 0.802202 -2.17373e-05 0.000362389" mass="0.697801" diaginertia="0.00116267 0.00100065 0.000614359"/>
                    <geom type="mesh" contype="0" conaffinity="0" group="1" density="0" rgba="0 0.5 1 1" mesh="left_elbow_pitch"/>
                    <body name="left_elbow_yaw" pos="0 0.117 0.031" quat="0.499999 0.499999 -0.500001 0.500001">
                      <inertial pos="3.656e-05 0.00424199 -0.0542142" quat="0.996462 0.0840255 0.000993479 0.00116848" mass="0.287879" diaginertia="0.000714861 0.000702477 0.000540322"/>
                      <geom type="mesh" contype="0" conaffinity="0" group="1" density="0" rgba="0.8 1 0.8 1" mesh="left_elbow_yaw"/>
                      <body name="left_wrist_pitch" pos="0.006 9.9998e-05 -0.1394" quat="0.707105 0.707108 0 0">
                        <inertial pos="-9.994e-05 0 0.00229425" quat="0.5 0.5 0.5 0.5" mass="0.00900738" diaginertia="5.7e-07 3.8e-07 2.4e-07"/>
                        <geom type="mesh" contype="0" conaffinity="0" group="1" density="0" rgba="1 0.5 1 1" mesh="left_wrist_pitch"/>
                      </body>
                      <body name="arm_l_wrist_a_ball" pos="-0.009 -0.02 -0.0199" quat="0.707105 0.707108 0 0">
                        <inertial pos="0.00076586 -0.0115683 4.912e-05" quat="0.490941 0.50421 -0.49667 0.508004" mass="0.235987" diaginertia="7.97705e-05 7.63707e-05 2.51588e-05"/>
                        <geom type="mesh" contype="0" conaffinity="0" group="1" density="0" rgba="1 1 1 1" mesh="arm_r_wrist_a_ball"/>
                        <body name="arm_l_wrist_motor_a_link" pos="0.0027628 -0.097124 0" quat="0.707034 0.707037 0.010054 0.010054">
                          <inertial pos="0 0 0.00973737" quat="0.707107 0 0 0.707107" mass="0.00117982" diaginertia="8e-08 6e-08 2e-08"/>
                          <geom type="mesh" contype="0" conaffinity="0" group="1" density="0" rgba="1 1 1 1" mesh="arm_r_wrist_motor_a_link"/>
                          <body name="arm_l_wrist_a_loop" pos="0 0 0.0132" quat="0.707034 -0.707037 -0.010054 -0.010054">
                            <inertial pos="0 0 -1.922e-05" mass="0.00548041" diaginertia="8e-08 8e-08 7e-08"/>
                            <geom type="mesh" contype="0" conaffinity="0" group="1" density="0" rgba="1 1 1 1" mesh="arm_r_wrist_a_loop"/>
                          </body>
                        </body>
                      </body>
                      <body name="arm_l_wrist_b_ball" pos="-0.009 0.02 -0.0199" quat="0.707105 -0.707108 0 0">
                        <inertial pos="0.00121967 0.0441726 0" quat="0.707014 0.707014 -0.0114787 -0.0114787" mass="0.0361757" diaginertia="1.73133e-05 1.731e-05 4.67668e-06"/>
                        <geom type="mesh" contype="0" conaffinity="0" group="1" density="0" rgba="1 1 1 1" mesh="arm_r_wrist_b_ball"/>
                        <body name="arm_l_wrist_motor_b_link" pos="0.0027628 0.097124 0" quat="0.707034 -0.707037 0.010054 -0.010054">
                          <inertial pos="0.00076586 0.0115683 -4.912e-05" quat="0.508004 0.49667 -0.50421 0.490941" mass="0.235987" diaginertia="7.97705e-05 7.63707e-05 2.51588e-05"/>
                          <geom type="mesh" contype="0" conaffinity="0" group="1" density="0" rgba="1 1 1 1" mesh="arm_r_wrist_motor_b_link"/>
                          <body name="arm_l_wrist_b_loop" pos="0 0 0.0132" quat="0.707034 0.707037 -0.010054 0.010054">
                            <inertial pos="0 0 0.00973737" quat="0.707107 0 0 0.707107" mass="0.00117982" diaginertia="8e-08 6e-08 2e-08"/>
                            <geom type="mesh" contype="0" conaffinity="0" group="1" density="0" rgba="1 1 1 1" mesh="arm_r_wrist_b_loop"/>
                          </body>
                        </body>
                      </body>
                    </body>
                  </body>
                </body>
              </body>
            </body>
            <body name="right_shoulder_pitch" pos="0 0.256 0.1458" quat="-3.67321e-06 1 0 0">
              <inertial pos="0.00250704 -0.00149173 -0.0567433" quat="0.995977 -0.00568417 0.0346063 -0.0824611" mass="1.00679" diaginertia="0.00108562 0.000958168 0.000853396"/>
              <geom type="mesh" contype="0" conaffinity="0" group="1" density="0" rgba="1 0.4 0.4 1" mesh="right_shoulder_pitch"/>
              <body name="right_shoulder_roll" pos="0.0313 0 -0.0592" quat="-2.59734e-06 0.707105 2.59735e-06 0.707108">
                <inertial pos="9.998e-05 -0.0778724 -0.0270563" quat="0.64355 0.765355 0.0062383 -0.00599871" mass="0.691426" diaginertia="0.00133761 0.00119704 0.000636294"/>
                <geom type="mesh" contype="0" conaffinity="0" group="1" density="0" rgba="1 0.4 0.4 1" mesh="right_shoulder_roll"/>
                <body name="right_shoulder_yaw" pos="0 -0.1252 -0.0313" quat="0.707105 0.707108 0 0">
                  <inertial pos="-0.00189082 -0.00017102 0.0317511" quat="0.694675 -0.204745 -0.19648 0.660985" mass="0.604503" diaginertia="0.000550567 0.000505158 0.000491905"/>
                  <geom type="mesh" contype="0" conaffinity="0" group="1" density="0" rgba="1 1 0.4 1" mesh="right_shoulder_yaw"/>
                  <body name="right_elbow_pitch" pos="-0.031 0 0.0365" quat="0.5 -0.5 0.5 -0.5">
                    <inertial pos="-2.604e-05 -0.0752983 0.0268563" quat="0.802034 0.597278 0.000362597 -2.24278e-05" mass="0.697801" diaginertia="0.00116302 0.00100116 0.000614171"/>
                    <geom type="mesh" contype="0" conaffinity="0" group="1" density="0" rgba="0.4 1 0.4 1" mesh="right_elbow_pitch"/>
                    <body name="right_elbow_yaw" pos="0 -0.117 0.031" quat="0.499999 -0.499999 -0.500001 -0.500001">
                      <inertial pos="-3.65e-05 -0.00422926 -0.0541454" quat="0.99646 -0.0840546 -0.000988212 0.00116955" mass="0.288355" diaginertia="0.000715721 0.000703364 0.000540355"/>
                      <geom type="mesh" contype="0" conaffinity="0" group="1" density="0" rgba="0 0.5 1 1" mesh="right_elbow_yaw"/>
                      <body name="right_wrist_pitch" pos="0.006 9.9998e-05 -0.1394" quat="0.707105 0.707108 0 0">
                        <inertial pos="-9.994e-05 0 0.00229425" quat="0.5 0.5 0.5 0.5" mass="0.00900738" diaginertia="5.7e-07 3.8e-07 2.4e-07"/>
                        <geom type="mesh" contype="0" conaffinity="0" group="1" density="0" rgba="0.8 1 0.8 1" mesh="right_wrist_pitch"/>
                      </body>
                      <body name="arm_r_wrist_a_ball" pos="-0.009 -0.02 -0.0199" quat="0.707105 0.707108 0 0">
                        <inertial pos="0.00076586 -0.0115683 4.912e-05" quat="0.490941 0.50421 -0.49667 0.508004" mass="0.235987" diaginertia="7.97705e-05 7.63707e-05 2.51588e-05"/>
                        <geom type="mesh" contype="0" conaffinity="0" group="1" density="0" rgba="1 1 1 1" mesh="arm_r_wrist_a_ball"/>
                        <body name="arm_r_wrist_motor_a_link" pos="0.0027628 -0.097124 0" quat="0.707034 0.707037 0.010054 0.010054">
                          <inertial pos="0 0 0.00973737" quat="0.707107 0 0 0.707107" mass="0.00117982" diaginertia="8e-08 6e-08 2e-08"/>
                          <geom type="mesh" contype="0" conaffinity="0" group="1" density="0" rgba="1 1 1 1" mesh="arm_r_wrist_motor_a_link"/>
                          <body name="arm_r_wrist_a_loop" pos="0 0 0.0132" quat="0.707034 -0.707037 -0.010054 -0.010054">
                            <inertial pos="0 0 -1.922e-05" mass="0.00548041" diaginertia="8e-08 8e-08 7e-08"/>
                            <geom type="mesh" contype="0" conaffinity="0" group="1" density="0" rgba="1 1 1 1" mesh="arm_r_wrist_a_loop"/>
                          </body>
                        </body>
                      </body>
                      <body name="arm_r_wrist_b_ball" pos="-0.009 0.02 -0.0199" quat="0.707105 -0.707108 0 0">
                        <inertial pos="0.00121967 0.0441726 0" quat="0.707014 0.707014 -0.0114787 -0.0114787" mass="0.0361757" diaginertia="1.73133e-05 1.731e-05 4.67668e-06"/>
                        <geom type="mesh" contype="0" conaffinity="0" group="1" density="0" rgba="1 1 1 1" mesh="arm_r_wrist_b_ball"/>
                        <body name="arm_r_wrist_motor_b_link" pos="0.0027628 0.097124 0" quat="0.707034 -0.707037 0.010054 -0.010054">
                          <inertial pos="0 0 0.00973737" quat="0.707107 0 0 0.707107" mass="0.00117982" diaginertia="8e-08 6e-08 2e-08"/>
                          <geom type="mesh" contype="0" conaffinity="0" group="1" density="0" rgba="1 1 1 1" mesh="arm_r_wrist_motor_b_link"/>
                          <body name="arm_r_wrist_b_loop" pos="0 0 0.0132" quat="0.707034 0.707037 -0.010054 0.010054">
                            <inertial pos="0 0 -1.922e-05" mass="0.00548041" diaginertia="8e-08 8e-08 7e-08"/>
                            <geom type="mesh" contype="0" conaffinity="0" group="1" density="0" rgba="1 1 1 1" mesh="arm_r_wrist_b_loop"/>
                          </body>
                        </body>
                      </body>
                    </body>
                  </body>
                </body>
              </body>
            </body>
            <body name="waist_motor_a_link" pos="0 0.075 0.0708">
              <inertial pos="-0.0404684 0 -0.00673515" quat="0.00694635 0.603061 0.00566511 0.797645" mass="0.058187" diaginertia="5.09864e-05 5.05299e-05 6.75372e-06"/>
              <geom type="mesh" contype="0" conaffinity="0" group="1" density="0" rgba="0.776471 0.756863 0.737255 1" mesh="waist_motor_a_link"/>
              <body name="waist_motor_a_ball" pos="-0.065 0 -0.0108" quat="0 1 0 0">
                <inertial pos="-0.00179727 0.0374998 -3.559e-05" quat="0.5 0.5 -0.5 0.5" mass="0.036139" diaginertia="3.624e-05 3.412e-05 2.43e-06"/>
                <geom type="mesh" contype="0" conaffinity="0" group="1" density="0" rgba="0.776471 0.756863 0.737255 1" mesh="waist_motor_a_ball"/>
                <body name="waist_motor_a_loop" pos="0 0.075 0" quat="0 1 0 0">
                  <inertial pos="0 0 0.00052471" mass="0.017653" diaginertia="8e-07 8e-07 3.5e-07"/>
                  <geom type="mesh" contype="0" conaffinity="0" group="1" density="0" rgba="1 1 1 1" mesh="waist_motor_a_loop"/>
                </body>
              </body>
            </body>
            <body name="waist_motor_b_link" pos="0 0.075 -0.0708" quat="0 1 0 0">
              <inertial pos="-0.0404684 0 -0.00673515" quat="0.00694635 0.603061 0.00566511 0.797645" mass="0.058187" diaginertia="5.09864e-05 5.05299e-05 6.75372e-06"/>
              <geom type="mesh" contype="0" conaffinity="0" group="1" density="0" rgba="0.776471 0.756863 0.737255 1" mesh="waist_motor_b_link"/>
              <body name="waist_motor_b_ball" pos="-0.065 0 -0.0108" quat="0 0.707107 0 -0.707107">
                <inertial pos="3.559e-05 -0.0374998 0.00179727" quat="0.707107 0.707107 0 0" mass="0.036139" diaginertia="3.624e-05 3.412e-05 2.43e-06"/>
                <geom type="mesh" contype="0" conaffinity="0" group="1" density="0" rgba="1 1 1 1" mesh="waist_motor_b_ball"/>
                <body name="waist_motor_b_loop" pos="0 -0.075 0">
                  <inertial pos="-0.00052471 0 0" quat="0.5 0.5 0.5 0.5" mass="0.017653" diaginertia="8e-07 8e-07 3.5e-07"/>
                  <geom type="mesh" contype="0" conaffinity="0" group="1" density="0" rgba="1 1 1 1" mesh="waist_motor_b_loop"/>
                </body>
              </body>
            </body>
          </body>
        </body>
      </body>
      <body name="left_hip_pitch" pos="0 0.1 0">
        <inertial pos="-4.816e-05 -0.0107584 -0.0540778" quat="0.701067 -0.0888726 0.120485 0.697202" mass="1.67336" diaginertia="0.00256418 0.00234466 0.00215142"/>
        <joint name="left_hip_pitch_joint" pos="0 0 0" axis="0 1 0" range="-3.14 3.14" actuatorfrcrange="-150 150"/>
        <geom pos="0.02 0.035 -0.12" type="mesh" contype="0" conaffinity="0" group="1" density="0" rgba="1 0.4 0.4 1" mesh="left_hip_pitch"/>
        <body name="left_hip_roll" pos="0 0.03 0" quat="0.499998 0.5 0.500002 0.5">
          <inertial pos="0.00014604 -0.0412348 -0.0101534" quat="0.30122 0.638429 -0.639374 0.304757" mass="0.285622" diaginertia="0.000612958 0.000557294 0.000275288"/>
          <joint name="left_hip_roll_joint" pos="0 0 0" axis="0 0 -1" range="-3.14 3.14" actuatorfrcrange="-150 150"/>
          <geom pos="0.005 0 0.02" quat="1 0 0 0" type="mesh" contype="0" conaffinity="0" group="1" density="0" rgba="1 1 0.4 1" mesh="left_hip_roll"/>
          <body name="left_hip_yaw" pos="0.006 -0.079 -0.018" quat="0.499998 -0.5 -0.5 -0.500002">
            <inertial pos="0 0 0" quat="0.999467 0.000387515 -0.0324521 -0.0035558" mass="2.73696" diaginertia="0.0127474 0.0124495 0.00338744"/>
            <joint name="left_hip_yaw_joint" pos="0 0 0" axis="0 0 -1" range="-3.14 3.14" actuatorfrcrange="-50 50"/>
            <geom pos="0 0 -0.307" quat="1 0 0 0" type="mesh" contype="0" conaffinity="0" group="1" density="0" rgba="0.4 1 0.4 1" mesh="left_hip_yaw"/>
            <body name="left_knee_pitch" pos="0 -0.02 -0.235" quat="-2.59734e-06 -2.59735e-06 0.707108 0.707105">
              <inertial pos="-0.0047354 -0.131013 0.0279688" quat="0.558496 0.482933 -0.445998 0.505908" mass="1.51226" diaginertia="0.00838281 0.00806462 0.00162062"/>
              <joint name="left_knee_pitch_joint" pos="0 0 0" axis="0 0 1" range="-3.14 3.14" actuatorfrcrange="-150 150"/>
              <geom pos="0 0 -0.01" quat="1 0 0 0" type="mesh" contype="0" conaffinity="0" group="1" density="0" rgba="0 0.5 1 1" mesh="left_knee_pitch"/>
              <body name="left_ankle_pitch" pos="0 -0.30494 0.0336" quat="0 0 -1 0">
                <inertial pos="-2.32e-06 7.077e-05 -2.048e-05" quat="0.707107 0 0 0.707107" mass="0.0621721" diaginertia="2.373e-05 2.273e-05 6.68e-06"/>
                <joint name="left_ankle_pitch_joint" pos="0 0 0" axis="0 0 -1" range="-3.14 3.14" actuatorfrcrange="-80 80"/>
                <geom type="mesh" contype="0" conaffinity="0" group="1" density="0" rgba="0 0.5 1 1" mesh="left_ankle_pitch"/>
                <body name="left_ankle_roll" quat="0.707107 0 0.707107 0">
                  <inertial pos="0.00017156 -0.025247 -0.00019936" quat="0.707585 0.0111979 -0.0139853 0.706401" mass="0.589712" diaginertia="0.00190069 0.00152114 0.000541391"/>
                  <joint name="left_ankle_roll_joint" pos="0 0 0" axis="0 0 1" range="-1.57 1.57" actuatorfrcrange="-80 80"/>
                  <geom type="mesh" contype="0" conaffinity="0" group="1" density="0" rgba="1 0.5 1 1" mesh="left_ankle_roll"/>
                  <geom type="mesh" rgba="1 0.5 1 1" mesh="left_ankle_roll"/>
                </body>
              </body>
              <body name="leg_l_toe_a_link" pos="0.01985 -0.109962 0.0336568" quat="0.707107 0 -0.707107 0">
                <inertial pos="-0.00875902 0.00339112 -0.00875449" quat="0.146527 0.583456 -0.108414 0.791426" mass="0.0311417" diaginertia="9.28705e-06 8.02562e-06 3.25733e-06"/>
                <geom type="mesh" contype="0" conaffinity="0" group="1" density="0" rgba="1 1 1 1" mesh="leg_l_toe_a_link"/>
                <body name="leg_l_toe_a_ball" pos="-0.0233806 0.00902193 -0.02115">
                  <inertial pos="-1.914e-05 -0.0941377 1.9e-06" quat="0.500119 0.499914 -0.500109 0.499859" mass="0.0567471" diaginertia="0.00022113 0.00022106 1.08995e-06"/>
                  <geom type="mesh" contype="0" conaffinity="0" group="1" density="0" rgba="1 1 1 1" mesh="leg_l_toe_a_ball"/>
                  <body name="leg_l_toe_a_loop" pos="0 -0.195 0" quat="0.707107 0 0.707107 0">
                    <inertial pos="0 0 -0.0006502" mass="0.0062017" diaginertia="2.8e-07 2.8e-07 1.2e-07"/>
                    <geom type="mesh" contype="0" conaffinity="0" group="1" density="0" rgba="1 1 1 1" mesh="leg_l_toe_a_loop"/>
                  </body>
                </body>
              </body>
              <body name="leg_l_toe_b_link" pos="0.01985 -0.164962 0.0335432" quat="0.707107 0 -0.707107 0">
                <inertial pos="0.0089831 0.00345524 -0.00906395" quat="-0.106739 0.798862 0.149404 0.572804" mass="0.03161" diaginertia="9.50881e-06 8.37471e-06 3.40648e-06"/>
                <geom type="mesh" contype="0" conaffinity="0" group="1" density="0" rgba="1 1 1 1" mesh="leg_l_toe_b_link"/>
                <body name="leg_l_toe_b_ball" pos="0.0233806 0.00902193 -0.02115">
                  <inertial pos="-2.566e-05 -0.0667639 2.566e-05" quat="0.500193 0.500193 -0.500193 0.499422" mass="0.0423305" diaginertia="9.17901e-05 9.17201e-05 9.49892e-07"/>
                  <geom type="mesh" contype="0" conaffinity="0" group="1" density="0" rgba="1 1 1 1" mesh="leg_l_toe_b_ball"/>
                  <body name="leg_l_toe_b_loop" pos="0 -0.14 0" quat="0.707107 0 0.707107 0">
                    <inertial pos="0 0 0.00064901" mass="0.0062017" diaginertia="2.8e-07 2.8e-07 1.2e-07"/>
                    <geom type="mesh" contype="0" conaffinity="0" group="1" density="0" rgba="1 1 1 1" mesh="leg_l_toe_b_loop"/>
                  </body>
                </body>
              </body>
            </body>
          </body>
        </body>
      </body>
      <body name="right_hip_pitch" pos="0 -0.1 0">
        <inertial pos="-0.00011915 0.0106148 -0.0540773" quat="0.704635 0.117558 -0.0919818 0.693692" mass="1.66657" diaginertia="0.00254519 0.00232121 0.00213313"/>
        <joint name="right_hip_pitch_joint" pos="0 0 0" axis="0 1 0" range="-3.14 3.14" actuatorfrcrange="-150 150"/>
        <geom pos="0.02 -0.04 -0.12" type="mesh" contype="0" conaffinity="0" group="1" density="0" rgba="1 0.4 0.4 1" mesh="right_hip_pitch"/>
        <body name="right_hip_roll" pos="0 -0.03 0" quat="0.499998 0.5 -0.500002 -0.5">
          <inertial pos="-0.00027058 -0.0416462 0.0103426" quat="0.633195 0.29395 -0.315414 0.642785" mass="0.287688" diaginertia="0.000626566 0.000566795 0.000280389"/>
          <joint name="right_hip_roll_joint" pos="0 0 0" axis="0 0 1" range="-3.14 3.14" actuatorfrcrange="-150 150"/>
          <geom pos="0.01 0 -0.02" quat="1 0 0 0" type="mesh" contype="0" conaffinity="0" group="1" density="0" rgba="1 1 0.4 1" mesh="right_hip_roll"/>
          <body name="right_hip_yaw" pos="0.01 -0.079 0.018" quat="0.499998 -0.5 0.5 0.500002">
            <inertial pos="-0.00241642 1.672e-05 -0.097047" quat="0.999478 -0.000259753 0.0322929 -0.00102692" mass="2.69635" diaginertia="0.0125794 0.0122506 0.00332533"/>
            <joint name="right_hip_yaw_joint" pos="0 0 0" axis="0 0 1" range="-3.14 3.14" actuatorfrcrange="-50 50"/>
            <geom pos="0 0 -0.307" quat="1 0 0 0" type="mesh" contype="0" conaffinity="0" group="1" density="0" rgba="0.4 1 0.4 1" mesh="right_hip_yaw"/>
            <body name="right_knee_pitch" pos="0 0.02 -0.235" quat="0.707105 0.707108 0 0">
              <inertial pos="0.00477062 -0.131723 0.0279383" quat="0.506605 0.444964 -0.483685 0.558039" mass="1.50954" diaginertia="0.0083387 0.00801985 0.00161715"/>
              <joint name="right_knee_pitch_joint" pos="0 0 0" axis="0 0 -1" range="-3.14 3.14" actuatorfrcrange="-150 150"/>
              <geom pos="0 0 -0.01" quat="1 0 0 0" type="mesh" contype="0" conaffinity="0" group="1" density="0" rgba="0 0.5 1 1" mesh="right_knee_pitch"/>
              <body name="right_ankle_pitch" pos="0 -0.30494 0.0336" quat="0 1 0 0">
                <inertial pos="2.47e-06 -7.076e-05 -1.763e-05" quat="0.707107 -0.000207363 0.000207363 0.707107" mass="0.0621721" diaginertia="2.373e-05 2.273e-05 6.67999e-06"/>
                <joint name="right_ankle_pitch_joint" pos="0 0 0" axis="0 0 1" range="-3.14 3.14" actuatorfrcrange="-80 80"/>
                <geom type="mesh" contype="0" conaffinity="0" group="1" density="0" rgba="0 0.5 1 1" mesh="right_ankle_pitch"/>
                <body name="right_ankle_roll" quat="0.707107 0 0.707107 0">
                  <inertial pos="-2.32e-06 0.0250789 0.00010556" quat="0.707007 -0.0123369 0.0123002 0.706992" mass="0.591828" diaginertia="0.00189406 0.00151845 0.00054237"/>
                  <joint name="right_ankle_roll_joint" pos="0 0 0" axis="0 0 1" range="-1.57 1.57" actuatorfrcrange="-80 80"/>
                  <geom type="mesh" contype="0" conaffinity="0" group="1" density="0" rgba="1 0.5 1 1" mesh="right_ankle_roll"/>
                  <geom type="mesh" rgba="1 0.5 1 1" mesh="right_ankle_roll"/>
                </body>
              </body>
              <body name="leg_r_toe_a_link" pos="-0.01985 -0.109962 0.0336568" quat="0.707107 0 0.707107 0">
                <inertial pos="0.00876658 0.00337152 -0.00875449" quat="-0.108632 0.791117 0.149032 0.583201" mass="0.0311417" diaginertia="9.28916e-06 8.02493e-06 3.25591e-06"/>
                <geom type="mesh" contype="0" conaffinity="0" group="1" density="0" rgba="1 1 1 1" mesh="leg_r_toe_a_link"/>
                <body name="leg_r_toe_a_ball" pos="0.0233806 0.00902193 -0.02115">
                  <inertial pos="-1.914e-05 -0.0941377 1.914e-05" quat="0.500162 0.500162 -0.500065 0.49961" mass="0.0567471" diaginertia="0.00022113 0.00022106 1.08991e-06"/>
                  <geom type="mesh" contype="0" conaffinity="0" group="1" density="0" rgba="1 1 1 1" mesh="leg_r_toe_a_ball"/>
                  <body name="leg_r_toe_a_loop" pos="0 -0.195 0" quat="0.707107 0 0.707107 0">
                    <inertial pos="0 0 0.00064901" mass="0.0062017" diaginertia="2.8e-07 2.8e-07 1.2e-07"/>
                    <geom type="mesh" contype="0" conaffinity="0" group="1" density="0" rgba="1 1 1 1" mesh="leg_r_toe_a_loop"/>
                  </body>
                </body>
              </body>
              <body name="leg_r_toe_b_link" pos="-0.01985 -0.164962 0.0335432" quat="0.707107 0 0.707107 0">
                <inertial pos="-0.00897565 0.00347454 -0.00906395" quat="0.149785 0.573148 -0.105705 0.798682" mass="0.03161" diaginertia="9.50806e-06 8.3821e-06 3.39984e-06"/>
                <geom type="mesh" contype="0" conaffinity="0" group="1" density="0" rgba="1 1 1 1" mesh="leg_r_toe_b_link"/>
                <body name="leg_r_toe_b_ball" pos="-0.0233806 0.00902193 -0.02115">
                  <inertial pos="-2.566e-05 -0.0667639 2.566e-05" quat="0.500193 0.500193 -0.500193 0.499422" mass="0.0423305" diaginertia="9.17901e-05 9.17201e-05 9.49892e-07"/>
                  <geom type="mesh" contype="0" conaffinity="0" group="1" density="0" rgba="1 1 1 1" mesh="leg_r_toe_b_ball"/>
                  <body name="leg_r_toe_b_loop" pos="0 -0.14 0" quat="0.707107 0 0.707107 0">
                    <inertial pos="0 0 -0.00064901" mass="0.0062017" diaginertia="2.8e-07 2.8e-07 1.2e-07"/>
                    <geom type="mesh" contype="0" conaffinity="0" group="1" density="0" rgba="1 1 1 1" mesh="leg_r_toe_b_loop"/>
                  </body>
                </body>
              </body>
            </body>
          </body>
        </body>
      </body>
    </body>
  </worldbody>

  <actuator>
    <motor name = 'motor_left_hip_pitch' joint = 'left_hip_pitch_joint' ctrlrange = '-150 150' />
    <motor name = 'motor_left_hip_roll' joint = 'left_hip_roll_joint' ctrlrange = '-50 50' />
    <motor name = 'motor_left_hip_yaw' joint = 'left_hip_yaw_joint' ctrlrange = '-50 50' />
    <motor name = 'motor_left_knee_pitch' joint = 'left_knee_pitch_joint' ctrlrange = '-150 150' />
    <motor name = 'motor_left_ankle_pitch' joint = 'left_ankle_pitch_joint' ctrlrange = '-18 18' />
    <motor name = 'motor_left_ankle_roll' joint = 'left_ankle_roll_joint' ctrlrange = '-18 18' />

    <motor name = 'motor_right_hip_pitch' joint = 'right_hip_pitch_joint' ctrlrange = '-150 150' />
    <motor name = 'motor_right_hip_roll' joint = 'right_hip_roll_joint' ctrlrange = '-50 50' />
    <motor name = 'motor_right_hip_yaw' joint = 'right_hip_yaw_joint' ctrlrange = '-50 50' />
    <motor name = 'motor_right_knee_pitch' joint = 'right_knee_pitch_joint' ctrlrange = '-150 150' />
    <motor name = 'motor_right_ankle_pitch' joint = 'right_ankle_pitch_joint' ctrlrange = '-18 18' />
    <motor name = 'motor_right_ankle_roll' joint = 'right_ankle_roll_joint' ctrlrange = '-18 18' />
  </actuator>

  <sensor>
    <!-- imu sensor -->
    <framequat name="body-orientation" objtype="site" objname="imu" noise="0"/>
    <gyro name="body-angular-velocity" site="imu" noise="0.001"/>
    <framepos name="body-linear-pos" objtype="site" objname="imu"/>
    <velocimeter name="body-linear-vel" site="imu"/>
    <accelerometer name="body-linear-acceleration" site="imu" noise="0.001"/>

    <jointpos name = 'jointpos_left_hip_pitch' joint = 'left_hip_pitch_joint' noise = "0" />
    <jointpos name = 'jointpos_left_hip_roll' joint = 'left_hip_roll_joint' noise = "0" />
    <jointpos name = 'jointpos_left_hip_yaw' joint = 'left_hip_yaw_joint' noise = "0" />
    <jointpos name = 'jointpos_left_knee_pitch' joint = 'left_knee_pitch_joint' noise = "0" />
    <jointpos name = 'jointpos_left_ankle_pitch' joint = 'left_ankle_pitch_joint' noise = "0" />
    <jointpos name = 'jointpos_left_ankle_roll' joint = 'left_ankle_roll_joint' noise = "0" />

    <jointpos name = 'jointpos_right_hip_pitch' joint = 'right_hip_pitch_joint' noise = "0" />
    <jointpos name = 'jointpos_right_hip_roll' joint = 'right_hip_roll_joint' noise = "0" />
    <jointpos name = 'jointpos_right_hip_yaw' joint = 'right_hip_yaw_joint' noise = "0" />
    <jointpos name = 'jointpos_right_knee_pitch' joint = 'right_knee_pitch_joint' noise = "0" />
    <jointpos name = 'jointpos_right_ankle_pitch' joint = 'right_ankle_pitch_joint' noise = "0" />
    <jointpos name = 'jointpos_right_ankle_roll' joint = 'right_ankle_roll_joint' noise = "0" />

    <jointvel name = 'jointvel_left_hip_pitch' joint = 'left_hip_pitch_joint' noise = "0" />
    <jointvel name = 'jointvel_left_hip_roll' joint = 'left_hip_roll_joint' noise = "0" />
    <jointvel name = 'jointvel_left_hip_yaw' joint = 'left_hip_yaw_joint' noise = "0" />
    <jointvel name = 'jointvel_left_knee_pitch' joint = 'left_knee_pitch_joint' noise = "0" />
    <jointvel name = 'jointvel_left_ankle_pitch' joint = 'left_ankle_pitch_joint' noise = "0" />
    <jointvel name = 'jointvel_left_ankle_roll' joint = 'left_ankle_roll_joint' noise = "0" />

    <jointvel name = 'jointvel_right_hip_pitch' joint = 'right_hip_pitch_joint' noise = "0" />
    <jointvel name = 'jointvel_right_hip_roll' joint = 'right_hip_roll_joint' noise = "0" />
    <jointvel name = 'jointvel_right_hip_yaw' joint = 'right_hip_yaw_joint' noise = "0" />
    <jointvel name = 'jointvel_right_knee_pitch' joint = 'right_knee_pitch_joint' noise = "0" />
    <jointvel name = 'jointvel_right_ankle_pitch' joint = 'right_ankle_pitch_joint' noise = "0" />
    <jointvel name = 'jointvel_right_ankle_roll' joint = 'right_ankle_roll_joint' noise = "0" />
  </sensor>


  <keyframe>
    <key name = "home_default" qpos = "0 0 0.61 1 0 0 0 0.48891 0.06213 -0.33853 0.63204 -0.27224 0. -0.48891 -0.06213 0.33853 0.63204 -0.27224 0."/>
  </keyframe>
</mujoco>
